<robot name="amr">

    <link name="world"/>
    <joint name="world_to_base" type="fixed">
    <parent link="world"/>
    <child link="base_link"/>
    <origin xyz="0 0 0.1" rpy="0 0 0"/>
    </joint>
    
    <!-- CHASSIS-->
    <link name="base_link">
        <visual>
            <geometry>
                <box size="0.5 0.3 0.1"/>
            </geometry>
            <material name="blue">
                <color rgba="0 0 1 1"/>
            </material>
        </visual>

          <inertial>
            <mass value="5.0"/>
            <origin xyz="0 0 0"/>
            <inertia
            ixx="0.1" ixy="0" ixz="0"
            iyy="0.1" iyz="0"
            izz="0.1"/>
        </inertial>
    </link>

<!-- wheels -->
    <!-- front left wheel-->
    <link name="front_left_wheel">
        <visual>
            <geometry>
                <cylinder radius="0.1" length="0.04"/>
            </geometry>
            <material name="black">
                <color rgba="0 0 0 1"/>
            </material>
        </visual>

        <collision>
            <geometry>
                <cylinder radius="0.1" length="0.04"/>
            </geometry>
        </collision>

        <inertial>
            <mass value="0.5"/>
            <origin xyz="0 0 0"/>
            <inertia
            ixx="0.001"
            ixy="0"
            ixz="0"
            iyy="0.001"
            iyz="0"
            izz="0.001"/>
        </inertial>
    </link>

    <joint name="front_left_wheel_joint" type="continuous">
        <parent link="base_link"/>
        <child link="front_left_wheel"/>
        <origin xyz="0.2 0.17 0" rpy="1.5708  0 0"/>
        <axis xyz="0 0 1"/>
    </joint>

    <!-- front right wheel-->
    <link name="front_right_wheel">
        <visual>
            <geometry>
                <cylinder radius="0.1" length="0.04"/>
            </geometry>
            <material name="black">
                <color rgba="0 0 0 1"/>
            </material>
        </visual>

        <collision>
            <geometry>
                <cylinder radius="0.1" length="0.04"/>
            </geometry>
        </collision>

        <inertial>
            <mass value="0.5"/>
            <origin xyz="0 0 0"/>
            <inertia
            ixx="0.001"
            ixy="0"
            ixz="0"
            iyy="0.001"
            iyz="0"
            izz="0.001"/>
        </inertial>
    </link>

    <joint name="front_right_wheel_joint" type="continuous">
        <parent link="base_link"/>
        <child link="front_right_wheel"/>
        <origin xyz="0.2 -0.17 0" rpy="1.5708  0 0"/>
        <axis xyz="0 0 1"/>
    </joint>

    <!-- rear right wheel-->
    <link name = 'rear_right_wheel'>
        <visual>
            <geometry>
                <cylinder radius="0.1" length="0.04"/>
            </geometry>
            <material name="black">
                <color rgba="0 0 0 1"/>
            </material>
        </visual>

        <collision>
            <geometry>
                <cylinder radius="0.1" length="0.04"/>
            </geometry>
        </collision>

        <inertial>
            <mass value="0.5"/>
            <origin xyz="0 0 0"/>
            <inertia
            ixx="0.001"
            ixy="0"
            ixz="0"
            iyy="0.001"
            iyz="0"
            izz="0.001"/>
        </inertial>
    </link>

    <joint name = 'rear_right_wheel_joint' type ='continuous'>
        <parent link = 'base_link'/>
        <child link = 'rear_right_wheel'/>
        <origin xyz= '-0.2 -0.17 0' rpy = '1.5708  0 0'/>
        <axis xyz = '0 0 1'/>
    </joint>

    <!-- rear left wheel-->
    <link name = 'rear_left_wheel'>
        <visual>
            <geometry>
                <cylinder radius="0.1" length="0.04"/>
            </geometry>
            <material name="black">
                <color rgba="0 0 0 1"/>
            </material>
        </visual>

        <collision>
            <geometry>
                <cylinder radius="0.1" length="0.04"/>
            </geometry>
        </collision>

        <inertial>
            <mass value="0.5"/>
            <origin xyz="0 0 0"/>
            <inertia
            ixx="0.001"
            ixy="0"
            ixz="0"
            iyy="0.001"
            iyz="0"
            izz="0.001"/>
        </inertial>
    </link>

    <joint name = 'rear_left_wheel_joint' type ='continuous'>
        <parent link = 'base_link'/>
        <child link = 'rear_left_wheel'/>
        <origin xyz = '-0.2 0.17 0' rpy = '1.5708  0 0'/>
        <axis xyz = '0 0 1'/>
    </joint>


</robot>
